<?xml version="1.0" encoding="utf-8"?>
<!-- This URDF was automatically created by SolidWorks to URDF Exporter! Originally created by Stephen Brawner (brawner@gmail.com) 
     Commit Version: 1.6.0-4-g7f85cfe  Build Version: 1.6.7995.38578
     For more information, please see http://wiki.ros.org/sw_urdf_exporter -->
<robot
  name="Kinematic Model">
  <link
    name="base_link">
    <inertial>
      <origin
        xyz="0.125 0.011493 -0.12488"
        rpy="0 0 0" />
      <mass
        value="1.4323" />
      <inertia
        ixx="0.007515"
        ixy="5.5988E-23"
        ixz="4.1486E-20"
        iyy="0.014892"
        iyz="-4.4839E-06"
        izz="0.0075062" />
    </inertial>
    <visual>
      <origin
        xyz="0 0 0"
        rpy="0 0 0" />
      <geometry>
        <mesh
          filename="package://Kinematic Model/meshes/base_link.STL" />
      </geometry>
      <material
        name="">
        <color
          rgba="0.79216 0.81961 0.93333 1" />
      </material>
    </visual>
    <collision>
      <origin
        xyz="0 0 0"
        rpy="0 0 0" />
      <geometry>
        <mesh
          filename="package://Kinematic Model/meshes/base_link.STL" />
      </geometry>
    </collision>
  </link>
  <link
    name="link 1">
    <inertial>
      <origin
        xyz="1.35962641978349E-08 -4.49406609148717E-10 0.0499583991824579"
        rpy="0 0 0" />
      <mass
        value="0.745389957969349" />
      <inertia
        ixx="0.001236165400749"
        ixy="-2.28287179719541E-09"
        ixz="3.29901987186383E-10"
        iyy="0.0013781182334038"
        iyz="-4.34931645812276E-09"
        izz="0.00103853376973756" />
    </inertial>
    <visual>
      <origin
        xyz="0 0 0"
        rpy="0 0 0" />
      <geometry>
        <mesh
          filename="package://Kinematic Model/meshes/link 1.STL" />
      </geometry>
      <material
        name="">
        <color
          rgba="0.792156862745098 0.819607843137255 0.933333333333333 1" />
      </material>
    </visual>
    <collision>
      <origin
        xyz="0 0 0"
        rpy="0 0 0" />
      <geometry>
        <mesh
          filename="package://Kinematic Model/meshes/link 1.STL" />
      </geometry>
    </collision>
  </link>
  <joint
    name="joint1"
    type="continuous">
    <origin
      xyz="0.125 0.075 0.02286"
      rpy="0 0 1.5604" />
    <parent
      link="base_link" />
    <child
      link="link 1" />
    <axis
      xyz="0 0 1" />
    <limit
      lower="0"
      upper="0"
      effort="0"
      velocity="0" />
  </joint>
  <link
    name="link 2">
    <inertial>
      <origin
        xyz="-0.00253999999999972 -3.60822483003176E-16 0.1524"
        rpy="0 0 0" />
      <mass
        value="0.902412401721688" />
      <inertia
        ixx="0.00932089199361008"
        ixy="-1.62630325872826E-19"
        ixz="-1.9323786142186E-17"
        iyy="0.00934567259590456"
        iyz="1.15761891862489E-17"
        izz="0.000396566779325696" />
    </inertial>
    <visual>
      <origin
        xyz="0 0 0"
        rpy="0 0 0" />
      <geometry>
        <mesh
          filename="package://Kinematic Model/meshes/link 2.STL" />
      </geometry>
      <material
        name="">
        <color
          rgba="0.792156862745098 0.819607843137255 0.933333333333333 1" />
      </material>
    </visual>
    <collision>
      <origin
        xyz="0 0 0"
        rpy="0 0 0" />
      <geometry>
        <mesh
          filename="package://Kinematic Model/meshes/link 2.STL" />
      </geometry>
    </collision>
  </link>
  <joint
    name="joint2"
    type="continuous">
    <origin
      xyz="0 0 0.10478"
      rpy="0.56383 0 3.1416" />
    <parent
      link="link 1" />
    <child
      link="link 2" />
    <axis
      xyz="1 0 0" />
  </joint>
  <link
    name="link 3">
    <inertial>
      <origin
        xyz="2.09554595897998E-15 -0.244277581812725 -2.77555756156289E-16"
        rpy="0 0 0" />
      <mass
        value="1.40181180581322" />
      <inertia
        ixx="0.0284750839313573"
        ixy="2.1432644070965E-16"
        ixz="2.954450920023E-18"
        iyy="0.00248306633762882"
        iyz="-2.40844951175594E-17"
        izz="0.03035643992009" />
    </inertial>
    <visual>
      <origin
        xyz="0 0 0"
        rpy="0 0 0" />
      <geometry>
        <mesh
          filename="package://Kinematic Model/meshes/link 3.STL" />
      </geometry>
      <material
        name="">
        <color
          rgba="0.792156862745098 0.819607843137255 0.933333333333333 1" />
      </material>
    </visual>
    <collision>
      <origin
        xyz="0 0 0"
        rpy="0 0 0" />
      <geometry>
        <mesh
          filename="package://Kinematic Model/meshes/link 3.STL" />
      </geometry>
    </collision>
  </link>
  <joint
    name="joint3"
    type="continuous">
    <origin
      xyz="0 0 0.3048"
      rpy="2.7937 0 0" />
    <parent
      link="link 2" />
    <child
      link="link 3" />
    <axis
      xyz="1 0 0" />
  </joint>
  <link
    name="link 4">
    <inertial>
      <origin
        xyz="5.55111512312578E-17 -0.0190759946076534 -3.33066907387547E-16"
        rpy="0 0 0" />
      <mass
        value="0.194716381321943" />
      <inertia
        ixx="0.000189754557496878"
        ixy="-6.14098886759368E-21"
        ixz="-2.41172779395961E-20"
        iyy="9.84824842685725E-05"
        iyz="-2.47246407327359E-18"
        izz="0.000194597566216489" />
    </inertial>
    <visual>
      <origin
        xyz="0 0 0"
        rpy="0 0 0" />
      <geometry>
        <mesh
          filename="package://Kinematic Model/meshes/link 4.STL" />
      </geometry>
      <material
        name="">
        <color
          rgba="0.792156862745098 0.819607843137255 0.933333333333333 1" />
      </material>
    </visual>
    <collision>
      <origin
        xyz="0 0 0"
        rpy="0 0 0" />
      <geometry>
        <mesh
          filename="package://Kinematic Model/meshes/link 4.STL" />
      </geometry>
    </collision>
  </link>
  <joint
    name="joint4"
    type="continuous">
    <origin
      xyz="0 -0.4572 0"
      rpy="-0.19634 0 0" />
    <parent
      link="link 3" />
    <child
      link="link 4" />
    <axis
      xyz="1 0 0" />
  </joint>
  <link
    name="link 5">
    <inertial>
      <origin
        xyz="-4.16333634234434E-17 -0.0228654552938928 -5.68305317151796E-05"
        rpy="0 0 0" />
      <mass
        value="0.0345139192629378" />
      <inertia
        ixx="3.9382385101554E-05"
        ixy="-1.41348623073061E-20"
        ixz="2.08945822730895E-21"
        iyy="9.77314082989532E-06"
        iyz="4.48493188575489E-08"
        izz="4.18538740394483E-05" />
    </inertial>
    <visual>
      <origin
        xyz="0 0 0"
        rpy="0 0 0" />
      <geometry>
        <mesh
          filename="package://Kinematic Model/meshes/link 5.STL" />
      </geometry>
      <material
        name="">
        <color
          rgba="0.792156862745098 0.819607843137255 0.933333333333333 1" />
      </material>
    </visual>
    <collision>
      <origin
        xyz="0 0 0"
        rpy="0 0 0" />
      <geometry>
        <mesh
          filename="package://Kinematic Model/meshes/link 5.STL" />
      </geometry>
    </collision>
  </link>
  <joint
    name="joint5"
    type="continuous">
    <origin
      xyz="0 -0.0635 0"
      rpy="3.1416 0 3.0664" />
    <parent
      link="link 4" />
    <child
      link="link 5" />
    <axis
      xyz="0 0 1" />
  </joint>
  <link
    name="link 6">
    <inertial>
      <origin
        xyz="-9.41722116953869E-11 -0.0328909235037288 4.40709246873894E-10"
        rpy="0 0 0" />
      <mass
        value="0.0796493898468433" />
      <inertia
        ixx="5.11620079794089E-05"
        ixy="2.38561065746726E-13"
        ixz="-3.69564330581027E-13"
        iyy="3.64275780108535E-05"
        iyz="2.04359351249156E-12"
        izz="5.89921470193244E-05" />
    </inertial>
    <visual>
      <origin
        xyz="0 0 0"
        rpy="0 0 0" />
      <geometry>
        <mesh
          filename="package://Kinematic Model/meshes/link 6.STL" />
      </geometry>
      <material
        name="">
        <color
          rgba="0.792156862745098 0.819607843137255 0.933333333333333 1" />
      </material>
    </visual>
    <collision>
      <origin
        xyz="0 0 0"
        rpy="0 0 0" />
      <geometry>
        <mesh
          filename="package://Kinematic Model/meshes/link 6.STL" />
      </geometry>
    </collision>
  </link>
  <joint
    name="joint6"
    type="continuous">
    <origin
      xyz="0 -0.042878 0"
      rpy="-3.1416 0.060969 -3.1416" />
    <parent
      link="link 5" />
    <child
      link="link 6" />
    <axis
      xyz="0 1 0" />
  </joint>
  <link
    name="link 7">
    <inertial>
      <origin
        xyz="0.0173670166445763 -0.0253757568921502 5.55111512312578E-17"
        rpy="0 0 0" />
      <mass
        value="0.128452333914246" />
      <inertia
        ixx="9.8050670007244E-05"
        ixy="9.28005252876401E-06"
        ixz="-1.50771864611265E-19"
        iyy="4.96497082521551E-05"
        iyz="3.69253425443672E-20"
        izz="0.000135017996093339" />
    </inertial>
    <visual>
      <origin
        xyz="0 0 0"
        rpy="0 0 0" />
      <geometry>
        <mesh
          filename="package://Kinematic Model/meshes/link 7.STL" />
      </geometry>
      <material
        name="">
        <color
          rgba="0.792156862745098 0.819607843137255 0.933333333333333 1" />
      </material>
    </visual>
    <collision>
      <origin
        xyz="0 0 0"
        rpy="0 0 0" />
      <geometry>
        <mesh
          filename="package://Kinematic Model/meshes/link 7.STL" />
      </geometry>
    </collision>
  </link>
  <joint
    name="gripperJaws"
    type="continuous">
    <origin
      xyz="-0.0127 -0.071422 0"
      rpy="0 0 0.012961" />
    <parent
      link="link 6" />
    <child
      link="link 7" />
    <axis
      xyz="0 0 1" />
  </joint>
</robot>