<?xml version="1.0" encoding="utf-8"?>
<!-- This URDF was automatically created by SolidWorks to URDF Exporter! Originally created by Stephen Brawner (brawner@gmail.com) 
     Commit Version: 1.6.0-4-g7f85cfe  Build Version: 1.6.7995.38578
     For more information, please see http://wiki.ros.org/sw_urdf_exporter -->
<robot
  name="Kinematic Model">
  <link
    name="base_link">
    <inertial>
      <origin
        xyz="0.125 0.011493 -0.12488"
        rpy="0 0 0" />
      <mass
        value="1.4323" />
      <inertia
        ixx="0.007515"
        ixy="5.5988E-23"
        ixz="4.1486E-20"
        iyy="0.014892"
        iyz="-4.4839E-06"
        izz="0.0075062" />
    </inertial>
    <visual>
      <origin
        xyz="0 0 0"
        rpy="0 0 0" />
      <geometry>
        <mesh
          filename="package://Kinematic Model/meshes/base_link.STL" />
      </geometry>
      <material
        name="">
        <color
          rgba="0.79216 0.81961 0.93333 1" />
      </material>
    </visual>
    <collision>
      <origin
        xyz="0 0 0"
        rpy="0 0 0" />
      <geometry>
        <mesh
          filename="package://Kinematic Model/meshes/base_link.STL" />
      </geometry>
    </collision>
  </link>
  <link
    name="link 1">
    <inertial>
      <origin
        xyz="1.3596E-08 -4.4941E-10 0.049958"
        rpy="0 0 0" />
      <mass
        value="0.74539" />
      <inertia
        ixx="0.0012362"
        ixy="-2.2829E-09"
        ixz="3.299E-10"
        iyy="0.0013781"
        iyz="-4.3493E-09"
        izz="0.0010385" />
    </inertial>
    <visual>
      <origin
        xyz="0 0 0"
        rpy="0 0 0" />
      <geometry>
        <mesh
          filename="package://Kinematic Model/meshes/link 1.STL" />
      </geometry>
      <material
        name="">
        <color
          rgba="0.79216 0.81961 0.93333 1" />
      </material>
    </visual>
    <collision>
      <origin
        xyz="0 0 0"
        rpy="0 0 0" />
      <geometry>
        <mesh
          filename="package://Kinematic Model/meshes/link 1.STL" />
      </geometry>
    </collision>
  </link>
  <joint
    name="joint1"
    type="revolute">
    <origin
      xyz="0.125 0.075 0.02286"
      rpy="0 0 1.5604" />
    <parent
      link="base_link" />
    <child
      link="link 1" />
    <axis
      xyz="0 0 1" />
    <limit
      lower="-1.57"
      upper="1.57"
      effort="0"
      velocity="0" />
  </joint>
  <link
    name="link 2">
    <inertial>
      <origin
        xyz="-0.00254 -1.3878E-16 0.1524"
        rpy="0 0 0" />
      <mass
        value="0.90241" />
      <inertia
        ixx="0.0093209"
        ixy="5.2177E-19"
        ixz="3.2951E-18"
        iyy="0.0093457"
        iyz="1.802E-18"
        izz="0.00039657" />
    </inertial>
    <visual>
      <origin
        xyz="0 0 0"
        rpy="0 0 0" />
      <geometry>
        <mesh
          filename="package://Kinematic Model/meshes/link 2.STL" />
      </geometry>
      <material
        name="">
        <color
          rgba="0.79216 0.81961 0.93333 1" />
      </material>
    </visual>
    <collision>
      <origin
        xyz="0 0 0"
        rpy="0 0 0" />
      <geometry>
        <mesh
          filename="package://Kinematic Model/meshes/link 2.STL" />
      </geometry>
    </collision>
  </link>
  <joint
    name="joint2"
    type="revolute">
    <origin
      xyz="0 0 0.10478"
      rpy="0.034608 0 -3.1416" />
    <parent
      link="link 1" />
    <child
      link="link 2" />
    <axis
      xyz="1 0 0" />
    <limit
      lower="-4.71"
      upper="-1.57"
      effort="0"
      velocity="0" />
  </joint>
  <link
    name="link 3">
    <inertial>
      <origin
        xyz="-7.6328E-16 -0.24428 3.3307E-16"
        rpy="0 0 0" />
      <mass
        value="1.4018" />
      <inertia
        ixx="0.028475"
        ixy="-7.4503E-17"
        ixz="-1.3595E-19"
        iyy="0.0024831"
        iyz="4.5858E-17"
        izz="0.030356" />
    </inertial>
    <visual>
      <origin
        xyz="0 0 0"
        rpy="0 0 0" />
      <geometry>
        <mesh
          filename="package://Kinematic Model/meshes/link 3.STL" />
      </geometry>
      <material
        name="">
        <color
          rgba="0.79216 0.81961 0.93333 1" />
      </material>
    </visual>
    <collision>
      <origin
        xyz="0 0 0"
        rpy="0 0 0" />
      <geometry>
        <mesh
          filename="package://Kinematic Model/meshes/link 3.STL" />
      </geometry>
    </collision>
  </link>
  <joint
    name="joint3"
    type="revolute">
    <origin
      xyz="0 0 0.3048"
      rpy="3.1314 0 0" />
    <parent
      link="link 2" />
    <child
      link="link 3" />
    <axis
      xyz="1 0 0" />
    <limit
      lower="0"
      upper="3.14"
      effort="0"
      velocity="0" />
  </joint>
  <link
    name="link 4">
    <inertial>
      <origin
        xyz="0 -0.019076 0"
        rpy="0 0 0" />
      <mass
        value="0.19472" />
      <inertia
        ixx="0.00018975"
        ixy="-5.6116E-21"
        ixz="-1.1941E-20"
        iyy="9.8482E-05"
        iyz="9.1412E-19"
        izz="0.0001946" />
    </inertial>
    <visual>
      <origin
        xyz="0 0 0"
        rpy="0 0 0" />
      <geometry>
        <mesh
          filename="package://Kinematic Model/meshes/link 4.STL" />
      </geometry>
      <material
        name="">
        <color
          rgba="0.79216 0.81961 0.93333 1" />
      </material>
    </visual>
    <collision>
      <origin
        xyz="0 0 0"
        rpy="0 0 0" />
      <geometry>
        <mesh
          filename="package://Kinematic Model/meshes/link 4.STL" />
      </geometry>
    </collision>
  </link>
  <joint
    name="joint4"
    type="revolute">
    <origin
      xyz="0 -0.4572 0"
      rpy="-0.0047459 0 0" />
    <parent
      link="link 3" />
    <child
      link="link 4" />
    <axis
      xyz="1 0 0" />
    <limit
      lower="-1.57"
      upper="1.57"
      effort="0"
      velocity="0" />
  </joint>
  <link
    name="link 5">
    <inertial>
      <origin
        xyz="-4.1633E-17 -0.022865 -5.6831E-05"
        rpy="0 0 0" />
      <mass
        value="0.034514" />
      <inertia
        ixx="3.9382E-05"
        ixy="-1.7152E-20"
        ixz="1.3963E-21"
        iyy="9.7731E-06"
        iyz="4.4849E-08"
        izz="4.1854E-05" />
    </inertial>
    <visual>
      <origin
        xyz="0 0 0"
        rpy="0 0 0" />
      <geometry>
        <mesh
          filename="package://Kinematic Model/meshes/link 5.STL" />
      </geometry>
      <material
        name="">
        <color
          rgba="0.79216 0.81961 0.93333 1" />
      </material>
    </visual>
    <collision>
      <origin
        xyz="0 0 0"
        rpy="0 0 0" />
      <geometry>
        <mesh
          filename="package://Kinematic Model/meshes/link 5.STL" />
      </geometry>
    </collision>
  </link>
  <joint
    name="joint5"
    type="revolute">
    <origin
      xyz="0 -0.0635 0"
      rpy="3.1416 0 3.0664" />
    <parent
      link="link 4" />
    <child
      link="link 5" />
    <axis
      xyz="0 0 1" />
    <limit
      lower="-1.57"
      upper="1.57"
      effort="0"
      velocity="0" />
  </joint>
  <link
    name="link 6">
    <inertial>
      <origin
        xyz="-9.4172E-11 -0.032891 4.4071E-10"
        rpy="0 0 0" />
      <mass
        value="0.079649" />
      <inertia
        ixx="5.1162E-05"
        ixy="2.3856E-13"
        ixz="-3.6956E-13"
        iyy="3.6428E-05"
        iyz="2.0436E-12"
        izz="5.8992E-05" />
    </inertial>
    <visual>
      <origin
        xyz="0 0 0"
        rpy="0 0 0" />
      <geometry>
        <mesh
          filename="package://Kinematic Model/meshes/link 6.STL" />
      </geometry>
      <material
        name="">
        <color
          rgba="0.79216 0.81961 0.93333 1" />
      </material>
    </visual>
    <collision>
      <origin
        xyz="0 0 0"
        rpy="0 0 0" />
      <geometry>
        <mesh
          filename="package://Kinematic Model/meshes/link 6.STL" />
      </geometry>
    </collision>
  </link>
  <joint
    name="joint6"
    type="revolute">
    <origin
      xyz="0 -0.042878 0"
      rpy="-3.1416 0.060969 3.1416" />
    <parent
      link="link 5" />
    <child
      link="link 6" />
    <axis
      xyz="0 1 0" />
    <limit
      lower="-3.14"
      upper="3.14"
      effort="0"
      velocity="0" />
  </joint>
  <link
    name="link 7">
    <inertial>
      <origin
        xyz="0.017367 -0.025376 -2.7756E-16"
        rpy="0 0 0" />
      <mass
        value="0.12845" />
      <inertia
        ixx="9.8051E-05"
        ixy="9.2801E-06"
        ixz="-1.4569E-19"
        iyy="4.965E-05"
        iyz="2.6549E-20"
        izz="0.00013502" />
    </inertial>
    <visual>
      <origin
        xyz="0 0 0"
        rpy="0 0 0" />
      <geometry>
        <mesh
          filename="package://Kinematic Model/meshes/link 7.STL" />
      </geometry>
      <material
        name="">
        <color
          rgba="0.79216 0.81961 0.93333 1" />
      </material>
    </visual>
    <collision>
      <origin
        xyz="0 0 0"
        rpy="0 0 0" />
      <geometry>
        <mesh
          filename="package://Kinematic Model/meshes/link 7.STL" />
      </geometry>
    </collision>
  </link>
  <joint
    name="gripperJaws"
    type="continuous">
    <origin
      xyz="-0.0127 -0.0714222835216934 0"
      rpy="0 0 0.0129611415194016" />
    <parent
      link="link 6" />
    <child
      link="link 7" />
    <axis
      xyz="0 0 1" />
  </joint>
</robot>