<?xml version="1.0" encoding="utf-8"?>
<!-- This URDF was automatically created by SolidWorks to URDF Exporter! Originally created by Stephen Brawner (brawner@gmail.com) 
     Commit Version: 1.6.0-4-g7f85cfe  Build Version: 1.6.7995.38578
     For more information, please see http://wiki.ros.org/sw_urdf_exporter -->
<robot
  name="Kinematic Model">
  <link
    name="base_link">
    <inertial>
      <origin
        xyz="0.125 0.12488 0.011493"
        rpy="0 0 0" />
      <mass
        value="1.4323" />
      <inertia
        ixx="0.007515"
        ixy="-4.1486E-20"
        ixz="5.5988E-23"
        iyy="0.0075062"
        iyz="4.4839E-06"
        izz="0.014892" />
    </inertial>
    <visual>
      <origin
        xyz="0 0 0"
        rpy="0 0 0" />
      <geometry>
        <mesh
          filename="package://Kinematic Model/meshes/base_link.STL" />
      </geometry>
      <material
        name="">
        <color
          rgba="0.79216 0.81961 0.93333 1" />
      </material>
    </visual>
    <collision>
      <origin
        xyz="0 0 0"
        rpy="0 0 0" />
      <geometry>
        <mesh
          filename="package://Kinematic Model/meshes/base_link.STL" />
      </geometry>
    </collision>
  </link>
  <joint
    name="joint6"
    type="revolute">
    <origin
      xyz="0 -0.05 0"
      rpy="0 0 0" />
    <parent
      link="link 5" />
    <child
      link="link 6" />
    <axis
      xyz="0 1 0" />
    <limit
      lower="-6.28"
      upper="6.28"
      effort="0"
      velocity="1000" />
  </joint>
  <link
    name="link 1">
    <inertial>
      <origin
        xyz="1.3587E-08 -6.7876E-10 0.049958"
        rpy="0 0 0" />
      <mass
        value="0.74539" />
      <inertia
        ixx="0.0012362"
        ixy="2.3926E-06"
        ixz="2.5647E-10"
        iyy="0.0013781"
        iyz="-4.3543E-09"
        izz="0.0010385" />
    </inertial>
    <visual>
      <origin
        xyz="0 0 0"
        rpy="0 0 0" />
      <geometry>
        <mesh
          filename="package://Kinematic Model/meshes/link 1.STL" />
      </geometry>
      <material
        name="">
        <color
          rgba="0.79216 0.81961 0.93333 1" />
      </material>
    </visual>
    <collision>
      <origin
        xyz="0 0 0"
        rpy="0 0 0" />
      <geometry>
        <mesh
          filename="package://Kinematic Model/meshes/link 1.STL" />
      </geometry>
    </collision>
  </link>
  <joint
    name="joint1"
    type="revolute">
    <origin
      xyz="0 0 0"
      rpy="0 0 1.57" />
    <parent
      link="base_link" />
    <child
      link="link 1" />
    <axis
      xyz="0 0 1" />
    <limit
      lower="-1.57"
      upper="1.57"
      effort="0"
      velocity="1000" />
  </joint>
  <link
    name="link 2">
    <inertial>
      <origin
        xyz="-0.0026286 4.3583E-05 0.1524"
        rpy="0 0 0" />
      <mass
        value="0.90241" />
      <inertia
        ixx="0.0093209"
        ixy="4.1785E-07"
        ixz="5.2104E-06"
        iyy="0.0093457"
        iyz="-4.3814E-08"
        izz="0.00039657" />
    </inertial>
    <visual>
      <origin
        xyz="0 0 0"
        rpy="0 0 0" />
      <geometry>
        <mesh
          filename="package://Kinematic Model/meshes/link 2.STL" />
      </geometry>
      <material
        name="">
        <color
          rgba="0.79216 0.81961 0.93333 1" />
      </material>
    </visual>
    <collision>
      <origin
        xyz="0 0 0"
        rpy="0 0 0" />
      <geometry>
        <mesh
          filename="package://Kinematic Model/meshes/link 2.STL" />
      </geometry>
    </collision>
  </link>
  <joint
    name="joint2"
    type="revolute">
    <origin
      xyz="0 0 0.1"
      rpy="0 0 0" />
    <parent
      link="link 1" />
    <child
      link="link 2" />
    <axis
      xyz="1 0 0" />
    <limit
      lower="-1.57"
      upper="1.57"
      effort="0"
      velocity="1000" />
  </joint>
  <link
    name="link 3">
    <inertial>
      <origin
        xyz="0.0039426 -0.24424 -8.1084E-07"
        rpy="0 0 0" />
      <mass
        value="1.4018" />
      <inertia
        ixx="0.028468"
        ixy="0.00043838"
        ixz="7.753E-07"
        iyy="0.0024905"
        iyz="-8.3631E-08"
        izz="0.030356" />
    </inertial>
    <visual>
      <origin
        xyz="0 0 0"
        rpy="0 0 0" />
      <geometry>
        <mesh
          filename="package://Kinematic Model/meshes/link 3.STL" />
      </geometry>
      <material
        name="">
        <color
          rgba="0.79216 0.81961 0.93333 1" />
      </material>
    </visual>
    <collision>
      <origin
        xyz="0 0 0"
        rpy="0 0 0" />
      <geometry>
        <mesh
          filename="package://Kinematic Model/meshes/link 3.STL" />
      </geometry>
    </collision>
  </link>
  <joint
    name="joint3"
    type="revolute">
    <origin
      xyz="0 0 0.3"
      rpy="0 0 0" />
    <parent
      link="link 2" />
    <child
      link="link 3" />
    <axis
      xyz="1 0 0" />
    <limit
      lower="-1.57"
      upper="0"
      effort="0"
      velocity="1000" />
  </joint>
  <link
    name="link 4">
    <inertial>
      <origin
        xyz="0.0078561 -0.01901 -1.3012E-06"
        rpy="0 0 0" />
      <mass
        value="0.19472" />
      <inertia
        ixx="0.00018973"
        ixy="1.5396E-06"
        ixz="1.6084E-09"
        iyy="9.8508E-05"
        iyz="-2.4146E-10"
        izz="0.0001946" />
    </inertial>
    <visual>
      <origin
        xyz="0 0 0"
        rpy="0 0 0" />
      <geometry>
        <mesh
          filename="package://Kinematic Model/meshes/link 4.STL" />
      </geometry>
      <material
        name="">
        <color
          rgba="0.79216 0.81961 0.93333 1" />
      </material>
    </visual>
    <collision>
      <origin
        xyz="0 0 0"
        rpy="0 0 0" />
      <geometry>
        <mesh
          filename="package://Kinematic Model/meshes/link 4.STL" />
      </geometry>
    </collision>
  </link>
  <joint
    name="joint4"
    type="revolute">
    <origin
      xyz="0 -0.45 0"
      rpy="0 0 0" />
    <parent
      link="link 3" />
    <child
      link="link 4" />
    <axis
      xyz="1 0 0" />
    <limit
      lower="-1.57"
      upper="1.57"
      effort="0"
      velocity="1000" />
  </joint>
  <link
    name="link 5">
    <inertial>
      <origin
        xyz="-0.0085757 -0.022146 -5.6038E-05"
        rpy="0 0 0" />
      <mass
        value="0.034514" />
      <inertia
        ixx="3.9382E-05"
        ixy="1.0788E-10"
        ixz="8.1565E-10"
        iyy="9.7731E-06"
        iyz="4.3961E-08"
        izz="4.1854E-05" />
    </inertial>
    <visual>
      <origin
        xyz="0 0 0"
        rpy="0 0 0" />
      <geometry>
        <mesh
          filename="package://Kinematic Model/meshes/link 5.STL" />
      </geometry>
      <material
        name="">
        <color
          rgba="0.79216 0.81961 0.93333 1" />
      </material>
    </visual>
    <collision>
      <origin
        xyz="0 0 0"
        rpy="0 0 0" />
      <geometry>
        <mesh
          filename="package://Kinematic Model/meshes/link 5.STL" />
      </geometry>
    </collision>
  </link>
  <joint
    name="joint5"
    type="revolute">
    <origin
      xyz="0 -0.06 0"
      rpy="0 0 0" />
    <parent
      link="link 4" />
    <child
      link="link 5" />
    <axis
      xyz="0 0 1" />
    <limit
      lower="-1.57"
      upper="1.57"
      effort="0"
      velocity="1000" />
  </joint>
  <link
    name="link 6">
    <inertial>
      <origin
        xyz="0.011642 -0.071479 -0.00052076"
        rpy="0 0 0" />
      <mass
        value="0.2081" />
      <inertia
        ixx="0.00014896"
        ixy="9.9042E-06"
        ixz="-2.7747E-10"
        iyy="8.6326E-05"
        iyz="2.9981E-09"
        izz="0.00019401" />
    </inertial>
    <visual>
      <origin
        xyz="0 0 0"
        rpy="0 0 0" />
      <geometry>
        <mesh
          filename="package://Kinematic Model/meshes/link 6.STL" />
      </geometry>
      <material
        name="">
        <color
          rgba="0.79216 0.81961 0.93333 1" />
      </material>
    </visual>
    <collision>
      <origin
        xyz="0 0 0"
        rpy="0 0 0" />
      <geometry>
        <mesh
          filename="package://Kinematic Model/meshes/link 6.STL" />
      </geometry>
    </collision>
  </link>
  <joint
    name="joint6"
    type="revolute">
    <origin
      xyz="0 -0.05 0"
      rpy="0 0 0" />
    <parent
      link="link 5" />
    <child
      link="link 6" />
    <axis
      xyz="0 1 0" />
    <limit
      lower="-6.28"
      upper="6.28"
      effort="0"
      velocity="1000" />
  </joint>
</robot>