<?xml version="1.0" encoding="utf-8"?>
<!-- This URDF was automatically created by SolidWorks to URDF Exporter! Originally created by Stephen Brawner (brawner@gmail.com) 
     Commit Version: 1.6.0-4-g7f85cfe  Build Version: 1.6.7995.38578
     For more information, please see http://wiki.ros.org/sw_urdf_exporter -->
<robot
  name="Kinematic Model">
  <link
    name="base_link">
    <inertial>
      <origin
        xyz="0.125 0.124876444248601 0.0114927663217105"
        rpy="0 0 0" />
      <mass
        value="1.4322893517415" />
      <inertia
        ixx="0.00751499612969008"
        ixy="-4.14867237089862E-20"
        ixz="-7.80914496040444E-24"
        iyy="0.00750616961569954"
        iyz="4.48386910719772E-06"
        izz="0.0148917103717458" />
    </inertial>
    <visual>
      <origin
        xyz="0 0 0"
        rpy="0 0 0" />
      <geometry>
        <mesh
          filename="package://Kinematic Model/meshes/base_link.STL" />
      </geometry>
      <material
        name="">
        <color
          rgba="0.792156862745098 0.819607843137255 0.933333333333333 1" />
      </material>
    </visual>
    <collision>
      <origin
        xyz="0 0 0"
        rpy="0 0 0" />
      <geometry>
        <mesh
          filename="package://Kinematic Model/meshes/base_link.STL" />
      </geometry>
    </collision>
  </link>
  <link
    name="link 1">
    <inertial>
      <origin
        xyz="1.35867454786887E-08 -6.78758688144043E-10 0.0499583991824579"
        rpy="0 0 0" />
      <mass
        value="0.745389957969349" />
      <inertia
        ixx="0.00123620573969006"
        ixy="2.39261466397821E-06"
        ixz="2.5646694765674E-10"
        iyy="0.00137807789446274"
        iyz="-4.35426385031501E-09"
        izz="0.00103853376973756" />
    </inertial>
    <visual>
      <origin
        xyz="0 0 0"
        rpy="0 0 0" />
      <geometry>
        <mesh
          filename="package://Kinematic Model/meshes/link 1.STL" />
      </geometry>
      <material
        name="">
        <color
          rgba="0.792156862745098 0.819607843137255 0.933333333333333 1" />
      </material>
    </visual>
    <collision>
      <origin
        xyz="0 0 0"
        rpy="0 0 0" />
      <geometry>
        <mesh
          filename="package://Kinematic Model/meshes/link 1.STL" />
      </geometry>
    </collision>
  </link>
  <joint
    name="joint1"
    type="revolute">
    <origin
      xyz="0.125 0.075 0.02286"
      rpy="0 0 1.57" />
    <parent
      link="base_link" />
    <child
      link="link 1" />
    <axis
      xyz="0 0 1" />
    <limit
      lower="-1.57"
      upper="1.57"
      effort="0"
      velocity="1000" />
  </joint>
  <link
    name="link 2">
    <inertial>
      <origin
        xyz="-0.00262861596537148 4.35832410141668E-05 0.152398491064077"
        rpy="0 0 0" />
      <mass
        value="0.902412401721688" />
      <inertia
        ixx="0.00932089599849758"
        ixy="4.17850665207742E-07"
        ixz="5.21040040008707E-06"
        iyy="0.00934566554874832"
        iyz="-4.3813581255483E-08"
        izz="0.000396569821594459" />
    </inertial>
    <visual>
      <origin
        xyz="0 0 0"
        rpy="0 0 0" />
      <geometry>
        <mesh
          filename="package://Kinematic Model/meshes/link 2.STL" />
      </geometry>
      <material
        name="">
        <color
          rgba="0.792156862745098 0.819607843137255 0.933333333333333 1" />
      </material>
    </visual>
    <collision>
      <origin
        xyz="0 0 0"
        rpy="0 0 0" />
      <geometry>
        <mesh
          filename="package://Kinematic Model/meshes/link 2.STL" />
      </geometry>
    </collision>
  </link>
  <joint
    name="joint2"
    type="revolute">
    <origin
      xyz="0 0 0.10478"
      rpy="0.034608 0 0" />
    <parent
      link="link 1" />
    <child
      link="link 2" />
    <axis
      xyz="1 0 0" />
    <limit
      lower="-1.57"
      upper="1.57"
      effort="0"
      velocity="1000" />
  </joint>
  <link
    name="link 3">
    <inertial>
      <origin
        xyz="0.00394263130754192 -0.244244326387476 -8.10835899700546E-07"
        rpy="0 0 0" />
      <mass
        value="1.40181180581322" />
      <inertia
        ixx="0.0284676883529979"
        ixy="0.000438382912247116"
        ixz="7.75299831865895E-07"
        iyy="0.00249046223456955"
        iyz="-8.36305080504878E-08"
        izz="0.0303564396015087" />
    </inertial>
    <visual>
      <origin
        xyz="0 0 0"
        rpy="0 0 0" />
      <geometry>
        <mesh
          filename="package://Kinematic Model/meshes/link 3.STL" />
      </geometry>
      <material
        name="">
        <color
          rgba="0.792156862745098 0.819607843137255 0.933333333333333 1" />
      </material>
    </visual>
    <collision>
      <origin
        xyz="0 0 0"
        rpy="0 0 0" />
      <geometry>
        <mesh
          filename="package://Kinematic Model/meshes/link 3.STL" />
      </geometry>
    </collision>
  </link>
  <joint
    name="joint3"
    type="revolute">
    <origin
      xyz="0 0 0.3048"
      rpy="1.57 0 0" />
    <parent
      link="link 2" />
    <child
      link="link 3" />
    <axis
      xyz="1 0 0" />
    <limit
      lower="0"
      upper="1.57"
      effort="0"
      velocity="1000" />
  </joint>
  <link
    name="link 4">
    <inertial>
      <origin
        xyz="0.0078561207187169 -0.0190097226424867 -1.30117151675435E-06"
        rpy="0 0 0" />
      <mass
        value="0.194716381321943" />
      <inertia
        ixx="0.000189728581597558"
        ixy="1.53956095211689E-06"
        ixz="1.60843658564306E-09"
        iyy="9.85084607001025E-05"
        iyz="-2.41458072488933E-10"
        izz="0.000194597565684406" />
    </inertial>
    <visual>
      <origin
        xyz="0 0 0"
        rpy="0 0 0" />
      <geometry>
        <mesh
          filename="package://Kinematic Model/meshes/link 4.STL" />
      </geometry>
      <material
        name="">
        <color
          rgba="0.792156862745098 0.819607843137255 0.933333333333333 1" />
      </material>
    </visual>
    <collision>
      <origin
        xyz="0 0 0"
        rpy="0 0 0" />
      <geometry>
        <mesh
          filename="package://Kinematic Model/meshes/link 4.STL" />
      </geometry>
    </collision>
  </link>
  <joint
    name="joint4"
    type="revolute">
    <origin
      xyz="0 -0.4572 0"
      rpy="-0.0047459 0 0" />
    <parent
      link="link 3" />
    <child
      link="link 4" />
    <axis
      xyz="1 0 0" />
    <limit
      lower="-1.57"
      upper="1.57"
      effort="0"
      velocity="1000" />
  </joint>
  <link
    name="link 5">
    <inertial>
      <origin
        xyz="-0.00857571960766509 -0.0221463464592254 -5.60381317857295E-05"
        rpy="0 0 0" />
      <mass
        value="0.034513919262938" />
      <inertia
        ixx="3.93823853704442E-05"
        ixy="1.07883205389676E-10"
        ixz="8.15651399396309E-10"
        iyy="9.77313837205837E-06"
        iyz="4.39613445525049E-08"
        izz="4.18538762283954E-05" />
    </inertial>
    <visual>
      <origin
        xyz="0 0 0"
        rpy="0 0 0" />
      <geometry>
        <mesh
          filename="package://Kinematic Model/meshes/link 5.STL" />
      </geometry>
      <material
        name="">
        <color
          rgba="0.792156862745098 0.819607843137255 0.933333333333333 1" />
      </material>
    </visual>
    <collision>
      <origin
        xyz="0 0 0"
        rpy="0 0 0" />
      <geometry>
        <mesh
          filename="package://Kinematic Model/meshes/link 5.STL" />
      </geometry>
    </collision>
  </link>
  <joint
    name="joint5"
    type="revolute">
    <origin
      xyz="0 -0.0635 0"
      rpy="0 0 0" />
    <parent
      link="link 4" />
    <child
      link="link 5" />
    <axis
      xyz="0 0 1" />
    <limit
      lower="-1.57"
      upper="1.57"
      effort="0"
      velocity="1000" />
  </joint>
  <link
    name="link 6">
    <inertial>
      <origin
        xyz="0.0116424667928664 -0.0714787044120002 -0.000520757328358434"
        rpy="0 0 0" />
      <mass
        value="0.20810172376109" />
      <inertia
        ixx="0.000148964014295915"
        ixy="9.90417507728737E-06"
        ixz="-2.77473331958715E-10"
        iyy="8.63259500372217E-05"
        iyz="2.99811306231378E-09"
        izz="0.00019401014302919" />
    </inertial>
    <visual>
      <origin
        xyz="0 0 0"
        rpy="0 0 0" />
      <geometry>
        <mesh
          filename="package://Kinematic Model/meshes/link 6.STL" />
      </geometry>
      <material
        name="">
        <color
          rgba="0.792156862745098 0.819607843137255 0.933333333333333 1" />
      </material>
    </visual>
    <collision>
      <origin
        xyz="0 0 0"
        rpy="0 0 0" />
      <geometry>
        <mesh
          filename="package://Kinematic Model/meshes/link 6.STL" />
      </geometry>
    </collision>
  </link>
  <joint
    name="joint6"
    type="revolute">
    <origin
      xyz="0 -0.042878 0"
      rpy="0 0 0" />
    <parent
      link="link 5" />
    <child
      link="link 6" />
    <axis
      xyz="0 1 0" />
    <limit
      lower="-6.28"
      upper="6.28"
      effort="0"
      velocity="1000" />
  </joint>
</robot>